<?xml version="1.0" encoding="utf-8" standalone="no"?>
<test-run id="0" runstate="Runnable" testcasecount="1" result="Failed" label="Error" total="1" passed="0" failed="1" warnings="0" inconclusive="0" skipped="0" asserts="0" engine-version="3.16.3.0" clr-version="4.0.30319.42000" start-time="2023-11-10 22:50:02Z" end-time="2023-11-10 22:50:04Z" duration="2.667448">
  <command-line><![CDATA["C:\Users\nikit\.nuget\packages\nunit.consolerunner\3.16.3\tools\nunit3-console.exe" ./TestSecond.dll]]></command-line>
  <test-suite type="Assembly" id="0" name="" fullname="" runstate="NotRunnable" testcasecount="1" result="Failed" label="Error" start-time="2023-11-10 22:50:04Z" end-time="2023-11-10 22:50:04Z" duration="0.001" total="1" passed="0" failed="1" inconclusive="0" skipped="0" asserts="0">
    <failure>
      <message><![CDATA[System.Net.Sockets.SocketException : Удаленный хост принудительно разорвал существующее подключение]]></message>
      <stack-trace><![CDATA[--SocketException
Удаленный хост принудительно разорвал существующее подключение
   в NUnit.Engine.Communication.Transports.Tcp.SocketReader.GetNextMessage()
   в NUnit.Engine.Communication.Transports.Tcp.TestAgentTcpProxy.TestRunResult(ITestEventListener listener)
   в NUnit.Engine.Runners.ProcessRunner.RunTests(ITestEventListener listener, TestFilter filter)
]]></stack-trace>
    </failure>
  </test-suite>
</test-run>